Workbook

Sheet Liste des courses
A1: Liste des courses – remplie automatiquement, ajustable à la main
A2: Les quantités calculées viennent des plats « Oui » et des articles d’hygiène « Oui ». Pour changer ce que vous achetez, tapez une quantité dans les colonnes jaunes « Qté à acheter (manuel) » : seul cet onglet change. Videz la cellule pour revenir au calcul automatique. Astuce : filtrez « Qté finale » pour masquer les lignes à 0.
B4: Total alimentation | C4: =SUM(K9:K90) -> 574.1121 | E4: Total calculé (sans ajustements) | G4: =SUMPRODUCT(F9:F90,J9:J90)+SUMPRODUCT(R9:R34,U9:U34) -> 718.0221
B5: Total hygiène & entretien | C5: =SUM(V9:V34) -> 143.91 | E5: Écart dû aux ajustements | G5: =C6-G4 -> 0
B6: TOTAL DES COURSES | C6: =C4+C5 -> 718.0221
A7: ALIMENTATION | N7: HYGIÈNE & ENTRETIEN
A8: n° | B8: Ingrédient | C8: En tounsi | D8: Qté recettes | E8: Unité | F8: Qté calculée | G8: Qté à acheter (manuel) | H8: Qté finale | I8: Unité d’achat | J8: Prix unitaire (DT) | K8: Coût (DT) | L8: ✓ | N8: n° | O8: Produit | P8: En tounsi | Q8: Format | R8: Qté prévue | S8: Qté à acheter (manuel) | T8: Qté finale | U8: Prix unitaire (DT) | V8: Coût (DT) | W8: ✓
A9: =IF($B9="","",1) -> 1 | B9: =IF(Listes!A1="","",Listes!A1) -> Escalopes de poulet | C9: =IF($B9="","",IFERROR(INDEX('Liste des ingrédients'!$C$5:$C$98,MATCH($B9,'Liste des ingrédients'!$B$5:$B$98,0)),"")) -> إسكالوب دجاج (escalope djej) | D9: =IF($B9="","",Listes!E1) -> 1800 | E9: =IF($B9="","",IF(I9="kg","g",IF(I9="L","ml",I9))) -> g | F9: =IF($B9="",0,IF(OR(I9="kg",I9="L"),ROUND(D9/1000,3),ROUNDUP(D9,0))) -> 1.8 | H9: =IF(G9="",F9,G9) -> 1.8 | I9: =IF($B9="","",IFERROR(INDEX('Liste des ingrédients'!$G$5:$G$98,MATCH($B9,'Liste des ingrédients'!$B$5:$B$98,0)),"")) -> kg | J9: =IF($B9="",0,IFERROR(INDEX('Liste des ingrédients'!$H$5:$H$98,MATCH($B9,'Liste des ingrédients'!$B$5:$B$98,0)),0)) -> 19.4 | K9: =IF($B9="",0,H9*J9) -> 34.92 | N9: =IF($O9="","",1) -> 1 | O9: =IF('Hygiène & entretien'!B6="","",'Hygiène & entretien'!B6) -> Savon de toilette | P9: =IF(O9="","",'Hygiène & entretien'!C6&"") -> صابون (saboun) | Q9: =IF(O9="","",'Hygiène & entretien'!D6&"") -> pain de 100 g | R9: =IF(O9="",0,IF('Hygiène & entretien'!E6="Oui",N('Hygiène & entretien'!F6),0)) -> 4 | T9: =IF(S9="",R9,S9) -> 4 | U9: =IF(O9="",0,N('Hygiène & entretien'!G6)) -> 1.8 | V9: =T9*U9 -> 7.2
A10: =IF($B10="","",2) -> 2 | B10: =IF(Listes!A2="","",Listes!A2) -> Cuisses de poulet | C10: =IF($B10="","",IFERROR(INDEX('Liste des ingrédients'!$C$5:$C$98,MATCH($B10,'Liste des ingrédients'!$B$5:$B$98,0)),"")) -> فخاذ دجاج (fkhadh djej) | D10: =IF($B10="","",Listes!E2) -> 3100 | E10: =IF($B10="","",IF(I10="kg","g",IF(I10="L","ml",I10))) -> g | F10: =IF($B10="",0,IF(OR(I10="kg",I10="L"),ROUND(D10/1000,3),ROUNDUP(D10,0))) -> 3.1 | H10: =IF(G10="",F10,G10) -> 3.1 | I10: =IF($B10="","",IFERROR(INDEX('Liste des ingrédients'!$G$5:$G$98,MATCH($B10,'Liste des ingrédients'!$B$5:$B$98,0)),"")) -> kg | J10: =IF($B10="",0,IFERROR(INDEX('Liste des ingrédients'!$H$5:$H$98,MATCH($B10,'Liste des ingrédients'!$B$5:$B$98,0)),0)) -> 14.9 | K10: =IF($B10="",0,H10*J10) -> 46.19 | N10: =IF($O10="","",2) -> 2 | O10: =IF('Hygiène & entretien'!B7="","",'Hygiène & entretien'!B7) -> Savon liquide pour les mains | P10: =IF(O10="","",'Hygiène & entretien'!C7&"") -> صابون سائل (saboun sayel) | Q10: =IF(O10="","",'Hygiène & entretien'!D7&"") -> flacon 1 L | R10: =IF(O10="",0,IF('Hygiène & entretien'!E7="Oui",N('Hygiène & entretien'!F7),0)) -> 1 | T10: =IF(S10="",R10,S10) -> 1 | U10: =IF(O10="",0,N('Hygiène & entretien'!G7)) -> 8.99 | V10: =T10*U10 -> 8.99
A11: =IF($B11="","",3) -> 3 | B11: =IF(Listes!A3="","",Listes!A3) -> Morceaux de poulet (pilons, hauts de cuisse) | C11: =IF($B11="","",IFERROR(INDEX('Liste des ingrédients'!$C$5:$C$98,MATCH($B11,'Liste des ingrédients'!$B$5:$B$98,0)),"")) -> طرف دجاج (traf djej) | D11: =IF($B11="","",Listes!E3) -> 1400 | E11: =IF($B11="","",IF(I11="kg","g",IF(I11="L","ml",I11))) -> g | F11: =IF($B11="",0,IF(OR(I11="kg",I11="L"),ROUND(D11/1000,3),ROUNDUP(D11,0))) -> 1.4 | H11: =IF(G11="",F11,G11) -> 1.4 | I11: =IF($B11="","",IFERROR(INDEX('Liste des ingrédients'!$G$5:$G$98,MATCH($B11,'Liste des ingrédients'!$B$5:$B$98,0)),"")) -> kg | J11: =IF($B11="",0,IFERROR(INDEX('Liste des ingrédients'!$H$5:$H$98,MATCH($B11,'Liste des ingrédients'!$B$5:$B$98,0)),0)) -> 14.9 | K11: =IF($B11="",0,H11*J11) -> 20.86 | N11: =IF($O11="","",3) -> 3 | O11: =IF('Hygiène & entretien'!B8="","",'Hygiène & entretien'!B8) -> Shampooing 2 en 1 | P11: =IF(O11="","",'Hygiène & entretien'!C8&"") -> شامبوان (shampoing) | Q11: =IF(O11="","",'Hygiène & entretien'!D8&"") -> flacon 400 ml | R11: =IF(O11="",0,IF('Hygiène & entretien'!E8="Oui",N('Hygiène & entretien'!F8),0)) -> 2 | T11: =IF(S11="",R11,S11) -> 2 | U11: =IF(O11="",0,N('Hygiène & entretien'!G8)) -> 5.65 | V11: =T11*U11 -> 11.3
A12: =IF($B12="","",4) -> 4 | B12: =IF(Listes!A4="","",Listes!A4) -> Blanc de poulet | C12: =IF($B12="","",IFERROR(INDEX('Liste des ingrédients'!$C$5:$C$98,MATCH($B12,'Liste des ingrédients'!$B$5:$B$98,0)),"")) -> صدر دجاج (sedr djej) | D12: =IF($B12="","",Listes!E4) -> 650 | E12: =IF($B12="","",IF(I12="kg","g",IF(I12="L","ml",I12))) -> g | F12: =IF($B12="",0,IF(OR(I12="kg",I12="L"),ROUND(D12/1000,3),ROUNDUP(D12,0))) -> 0.65 | H12: =IF(G12="",F12,G12) -> 0.65 | I12: =IF($B12="","",IFERROR(INDEX('Liste des ingrédients'!$G$5:$G$98,MATCH($B12,'Liste des ingrédients'!$B$5:$B$98,0)),"")) -> kg | J12: =IF($B12="",0,IFERROR(INDEX('Liste des ingrédients'!$H$5:$H$98,MATCH($B12,'Liste des ingrédients'!$B$5:$B$98,0)),0)) -> 19.4 | K12: =IF($B12="",0,H12*J12) -> 12.61 | N12: =IF($O12="","",4) -> 4 | O12: =IF('Hygiène & entretien'!B9="","",'Hygiène & entretien'!B9) -> Dentifrice | P12: =IF(O12="","",'Hygiène & entretien'!C9&"") -> معجون سنين (ma3joun snin) | Q12: =IF(O12="","",'Hygiène & entretien'!D9&"") -> tube 75 ml | R12: =IF(O12="",0,IF('Hygiène & entretien'!E9="Oui",N('Hygiène & entretien'!F9),0)) -> 2 | T12: =IF(S12="",R12,S12) -> 2 | U12: =IF(O12="",0,N('Hygiène & entretien'!G9)) -> 2.99 | V12: =T12*U12 -> 5.98
A13: =IF($B13="","",5) -> 5 | B13: =IF(Listes!A5="","",Listes!A5) -> Poulet pour spaghetti | C13: =IF($B13="","",IFERROR(INDEX('Liste des ingrédients'!$C$5:$C$98,MATCH($B13,'Liste des ingrédients'!$B$5:$B$98,0)),"")) -> دجاج (djej) | D13: =IF($B13="","",Listes!E5) -> 1000 | E13: =IF($B13="","",IF(I13="kg","g",IF(I13="L","ml",I13))) -> g | F13: =IF($B13="",0,IF(OR(I13="kg",I13="L"),ROUND(D13/1000,3),ROUNDUP(D13,0))) -> 1 | H13: =IF(G13="",F13,G13) -> 1 | I13: =IF($B13="","",IFERROR(INDEX('Liste des ingrédients'!$G$5:$G$98,MATCH($B13,'Liste des ingrédients'!$B$5:$B$98,0)),"")) -> kg | J13: =IF($B13="",0,IFERROR(INDEX('Liste des ingrédients'!$H$5:$H$98,MATCH($B13,'Liste des ingrédients'!$B$5:$B$98,0)),0)) -> 14.9 | K13: =IF($B13="",0,H13*J13) -> 14.9 | N13: =IF($O13="","",5) -> 5 | O13: =IF('Hygiène & entretien'!B10="","",'Hygiène & entretien'!B10) -> Brosses à dents | P13: =IF(O13="","",'Hygiène & entretien'!C10&"") -> فرشة سنين (forchet snin) | Q13: =IF(O13="","",'Hygiène & entretien'!D10&"") -> pièce | R13: =IF(O13="",0,IF('Hygiène & entretien'!E10="Oui",N('Hygiène & entretien'!F10),0)) -> 4 | T13: =IF(S13="",R13,S13) -> 4 | U13: =IF(O13="",0,N('Hygiène & entretien'!G10)) -> 1.59 | V13: =T13*U13 -> 6.36
A14: =IF($B14="","",6) -> 6 | B14: =IF(Listes!A6="","",Listes!A6) -> Bœuf à mijoter | C14: =IF($B14="","",IFERROR(INDEX('Liste des ingrédients'!$C$5:$C$98,MATCH($B14,'Liste des ingrédients'!$B$5:$B$98,0)),"")) -> لحم بقري (lham bagri) | D14: =IF($B14="","",Listes!E6) -> 1300 | E14: =IF($B14="","",IF(I14="kg","g",IF(I14="L","ml",I14))) -> g | F14: =IF($B14="",0,IF(OR(I14="kg",I14="L"),ROUND(D14/1000,3),ROUNDUP(D14,0))) -> 1.3 | H14: =IF(G14="",F14,G14) -> 1.3 | I14: =IF($B14="","",IFERROR(INDEX('Liste des ingrédients'!$G$5:$G$98,MATCH($B14,'Liste des ingrédients'!$B$5:$B$98,0)),"")) -> kg | J14: =IF($B14="",0,IFERROR(INDEX('Liste des ingrédients'!$H$5:$H$98,MATCH($B14,'Liste des ingrédients'!$B$5:$B$98,0)),0)) -> 47.5 | K14: =IF($B14="",0,H14*J14) -> 61.75 | N14: =IF($O14="","",6) -> 6 | O14: =IF('Hygiène & entretien'!B11="","",'Hygiène & entretien'!B11) -> Papier hygiénique | P14: =IF(O14="","",'Hygiène & entretien'!C11&"") -> كاغط توالات (kaghet twalet) | Q14: =IF(O14="","",'Hygiène & entretien'!D11&"") -> paquet de 12 rouleaux | R14: =IF(O14="",0,IF('Hygiène & entretien'!E11="Oui",N('Hygiène & entretien'!F11),0)) -> 2 | T14: =IF(S14="",R14,S14) -> 2 | U14: =IF(O14="",0,N('Hygiène & entretien'!G11)) -> 8.99 | V14: =T14*U14 -> 17.98
A15: =IF($B15="","",7) -> 7 | B15: =IF(Listes!A7="","",Listes!A7) -> Agneau | C15: =IF($B15="","",IFERROR(INDEX('Liste des ingrédients'!$C$5:$C$98,MATCH($B15,'Liste des ingrédients'!$B$5:$B$98,0)),"")) -> لحم علوش (lham 3allouch) | D15: =IF($B15="","",Listes!E7) -> 400 | E15: =IF($B15="","",IF(I15="kg","g",IF(I15="L","ml",I15))) -> g | F15: =IF($B15="",0,IF(OR(I15="kg",I15="L"),ROUND(D15/1000,3),ROUNDUP(D15,0))) -> 0.4 | H15: =IF(G15="",F15,G15) -> 0.4 | I15: =IF($B15="","",IFERROR(INDEX('Liste des ingrédients'!$G$5:$G$98,MATCH($B15,'Liste des ingrédients'!$B$5:$B$98,0)),"")) -> kg | J15: =IF($B15="",0,IFERROR(INDEX('Liste des ingrédients'!$H$5:$H$98,MATCH($B15,'Liste des ingrédients'!$B$5:$B$98,0)),0)) -> 60 | K15: =IF($B15="",0,H15*J15) -> 24 | N15: =IF($O15="","",7) -> 7 | O15: =IF('Hygiène & entretien'!B12="","",'Hygiène & entretien'!B12) -> Déodorant | P15: =IF(O15="","",'Hygiène & entretien'!C12&"") -> ديودوران (déodorant) | Q15: =IF(O15="","",'Hygiène & entretien'!D12&"") -> flacon 150 ml | R15: =IF(O15="",0,IF('Hygiène & entretien'!E12="Oui",N('Hygiène & entretien'!F12),0)) -> 2 | T15: =IF(S15="",R15,S15) -> 2 | U15: =IF(O15="",0,N('Hygiène & entretien'!G12)) -> 7 | V15: =T15*U15 -> 14
A16: =IF($B16="","",8) -> 8 | B16: =IF(Listes!A8="","",Listes!A8) -> Viande hachée | C16: =IF($B16="","",IFERROR(INDEX('Liste des ingrédients'!$C$5:$C$98,MATCH($B16,'Liste des ingrédients'!$B$5:$B$98,0)),"")) -> لحم مرحي (lham mor7i) | D16: =IF($B16="","",Listes!E8) -> 300 | E16: =IF($B16="","",IF(I16="kg","g",IF(I16="L","ml",I16))) -> g | F16: =IF($B16="",0,IF(OR(I16="kg",I16="L"),ROUND(D16/1000,3),ROUNDUP(D16,0))) -> 0.3 | H16: =IF(G16="",F16,G16) -> 0.3 | I16: =IF($B16="","",IFERROR(INDEX('Liste des ingrédients'!$G$5:$G$98,MATCH($B16,'Liste des ingrédients'!$B$5:$B$98,0)),"")) -> kg | J16: =IF($B16="",0,IFERROR(INDEX('Liste des ingrédients'!$H$5:$H$98,MATCH($B16,'Liste des ingrédients'!$B$5:$B$98,0)),0)) -> 45 | K16: =IF($B16="",0,H16*J16) -> 13.5 | N16: =IF($O16="","",8) -> 8 | O16: =IF('Hygiène & entretien'!B13="","",'Hygiène & entretien'!B13) -> Serviettes hygiéniques (selon besoin) | P16: =IF(O16="","",'Hygiène & entretien'!C13&"") -> فوطة صحية (fouta si77iya) | Q16: =IF(O16="","",'Hygiène & entretien'!D13&"") -> paquet | R16: =IF(O16="",0,IF('Hygiène & entretien'!E13="Oui",N('Hygiène & entretien'!F13),0)) -> 2 | T16: =IF(S16="",R16,S16) -> 2 | U16: =IF(O16="",0,N('Hygiène & entretien'!G13)) -> 4.5 | V16: =T16*U16 -> 9
A17: =IF($B17="","",9) -> 9 | B17: =IF(Listes!A9="","",Listes!A9) -> Foie | C17: =IF($B17="","",IFERROR(INDEX('Liste des ingrédients'!$C$5:$C$98,MATCH($B17,'Liste des ingrédients'!$B$5:$B$98,0)),"")) -> كبدة (kebda) | D17: =IF($B17="","",Listes!E9) -> 700 | E17: =IF($B17="","",IF(I17="kg","g",IF(I17="L","ml",I17))) -> g | F17: =IF($B17="",0,IF(OR(I17="kg",I17="L"),ROUND(D17/1000,3),ROUNDUP(D17,0))) -> 0.7 | H17: =IF(G17="",F17,G17) -> 0.7 | I17: =IF($B17="","",IFERROR(INDEX('Liste des ingrédients'!$G$5:$G$98,MATCH($B17,'Liste des ingrédients'!$B$5:$B$98,0)),"")) -> kg | J17: =IF($B17="",0,IFERROR(INDEX('Liste des ingrédients'!$H$5:$H$98,MATCH($B17,'Liste des ingrédients'!$B$5:$B$98,0)),0)) -> 45 | K17: =IF($B17="",0,H17*J17) -> 31.5 | N17: =IF($O17="","",9) -> 9 | O17: =IF('Hygiène & entretien'!B14="","",'Hygiène & entretien'!B14) -> Gel antibactérien | P17: =IF(O17="","",'Hygiène & entretien'!C14&"") -> جال معقم (gel m3aqqem) | Q17: =IF(O17="","",'Hygiène & entretien'!D14&"") -> flacon 125 ml | R17: =IF(O17="",0,IF('Hygiène & entretien'!E14="Oui",N('Hygiène & entretien'!F14),0)) -> 1 | T17: =IF(S17="",R17,S17) -> 1 | U17: =IF(O17="",0,N('Hygiène & entretien'!G14)) -> 3.69 | V17: =T17*U17 -> 3.69
A18: =IF($B18="","",10) -> 10 | B18: =IF(Listes!A10="","",Listes!A10) -> Merguez | C18: =IF($B18="","",IFERROR(INDEX('Liste des ingrédients'!$C$5:$C$98,MATCH($B18,'Liste des ingrédients'!$B$5:$B$98,0)),"")) -> مرقاز (mergaz) | D18: =IF($B18="","",Listes!E10) -> 500 | E18: =IF($B18="","",IF(I18="kg","g",IF(I18="L","ml",I18))) -> g | F18: =IF($B18="",0,IF(OR(I18="kg",I18="L"),ROUND(D18/1000,3),ROUNDUP(D18,0))) -> 0.5 | H18: =IF(G18="",F18,G18) -> 0.5 | I18: =IF($B18="","",IFERROR(INDEX('Liste des ingrédients'!$G$5:$G$98,MATCH($B18,'Liste des ingrédients'!$B$5:$B$98,0)),"")) -> kg | J18: =IF($B18="",0,IFERROR(INDEX('Liste des ingrédients'!$H$5:$H$98,MATCH($B18,'Liste des ingrédients'!$B$5:$B$98,0)),0)) -> 40 | K18: =IF($B18="",0,H18*J18) -> 20 | N18: =IF($O18="","",10) -> 10 | O18: =IF('Hygiène & entretien'!B17="","",'Hygiène & entretien'!B17) -> Liquide vaisselle | P18: =IF(O18="","",'Hygiène & entretien'!C17&"") -> صابون ماعون (saboun ma3oun) | Q18: =IF(O18="","",'Hygiène & entretien'!D17&"") -> flacon 960 ml | R18: =IF(O18="",0,IF('Hygiène & entretien'!E17="Oui",N('Hygiène & entretien'!F17),0)) -> 2 | T18: =IF(S18="",R18,S18) -> 2 | U18: =IF(O18="",0,N('Hygiène & entretien'!G17)) -> 6.69 | V18: =T18*U18 -> 13.38
A19: =IF($B19="","",11) -> 11 | B19: =IF(Listes!A11="","",Listes!A11) -> Poisson à chair ferme (mérou, loup, dorade) | C19: =IF($B19="","",IFERROR(INDEX('Liste des ingrédients'!$C$5:$C$98,MATCH($B19,'Liste des ingrédients'!$B$5:$B$98,0)),"")) -> حوت: مناني، قاروص، وراطة | D19: =IF($B19="","",Listes!E11) -> 1000 | E19: =IF($B19="","",IF(I19="kg","g",IF(I19="L","ml",I19))) -> g | F19: =IF($B19="",0,IF(OR(I19="kg",I19="L"),ROUND(D19/1000,3),ROUNDUP(D19,0))) -> 1 | H19: =IF(G19="",F19,G19) -> 1 | I19: =IF($B19="","",IFERROR(INDEX('Liste des ingrédients'!$G$5:$G$98,MATCH($B19,'Liste des ingrédients'!$B$5:$B$98,0)),"")) -> kg | J19: =IF($B19="",0,IFERROR(INDEX('Liste des ingrédients'!$H$5:$H$98,MATCH($B19,'Liste des ingrédients'!$B$5:$B$98,0)),0)) -> 22 | K19: =IF($B19="",0,H19*J19) -> 22 | N19: =IF($O19="","",11) -> 11 | O19: =IF('Hygiène & entretien'!B18="","",'Hygiène & entretien'!B18) -> Eau de javel | P19: =IF(O19="","",'Hygiène & entretien'!C18&"") -> جافال (javel) | Q19: =IF(O19="","",'Hygiène & entretien'!D18&"") -> bidon 3 L | R19: =IF(O19="",0,IF('Hygiène & entretien'!E18="Oui",N('Hygiène & entretien'!F18),0)) -> 1 | T19: =IF(S19="",R19,S19) -> 1 | U19: =IF(O19="",0,N('Hygiène & entretien'!G18)) -> 5.35 | V19: =T19*U19 -> 5.35
A20: =IF($B20="","",12) -> 12 | B20: =IF(Listes!A12="","",Listes!A12) -> Poisson blanc haché | C20: =IF($B20="","",IFERROR(INDEX('Liste des ingrédients'!$C$5:$C$98,MATCH($B20,'Liste des ingrédients'!$B$5:$B$98,0)),"")) -> حوت أبيض مرحي (7out abyedh mor7i) | D20: =IF($B20="","",Listes!E12) -> 600 | E20: =IF($B20="","",IF(I20="kg","g",IF(I20="L","ml",I20))) -> g | F20: =IF($B20="",0,IF(OR(I20="kg",I20="L"),ROUND(D20/1000,3),ROUNDUP(D20,0))) -> 0.6 | H20: =IF(G20="",F20,G20) -> 0.6 | I20: =IF($B20="","",IFERROR(INDEX('Liste des ingrédients'!$G$5:$G$98,MATCH($B20,'Liste des ingrédients'!$B$5:$B$98,0)),"")) -> kg | J20: =IF($B20="",0,IFERROR(INDEX('Liste des ingrédients'!$H$5:$H$98,MATCH($B20,'Liste des ingrédients'!$B$5:$B$98,0)),0)) -> 18 | K20: =IF($B20="",0,H20*J20) -> 10.8 | N20: =IF($O20="","",12) -> 12 | O20: =IF('Hygiène & entretien'!B19="","",'Hygiène & entretien'!B19) -> Nettoyant sol | P20: =IF(O20="","",'Hygiène & entretien'!C19&"") -> صابون القاعة (saboun el gaa3a) | Q20: =IF(O20="","",'Hygiène & entretien'!D19&"") -> bidon 3 L | R20: =IF(O20="",0,IF('Hygiène & entretien'!E19="Oui",N('Hygiène & entretien'!F19),0)) -> 1 | T20: =IF(S20="",R20,S20) -> 1 | U20: =IF(O20="",0,N('Hygiène & entretien'!G19)) -> 6.62 | V20: =T20*U20 -> 6.62
A21: =IF($B21="","",13) -> 13 | B21: =IF(Listes!A13="","",Listes!A13) -> Thon en boîte (160 g) | C21: =IF($B21="","",IFERROR(INDEX('Liste des ingrédients'!$C$5:$C$98,MATCH($B21,'Liste des ingrédients'!$B$5:$B$98,0)),"")) -> تن (ton) | D21: =IF($B21="","",Listes!E13) -> 6 | E21: =IF($B21="","",IF(I21="kg","g",IF(I21="L","ml",I21))) -> boîte | F21: =IF($B21="",0,IF(OR(I21="kg",I21="L"),ROUND(D21/1000,3),ROUNDUP(D21,0))) -> 6 | H21: =IF(G21="",F21,G21) -> 6 | I21: =IF($B21="","",IFERROR(INDEX('Liste des ingrédients'!$G$5:$G$98,MATCH($B21,'Liste des ingrédients'!$B$5:$B$98,0)),"")) -> boîte | J21: =IF($B21="",0,IFERROR(INDEX('Liste des ingrédients'!$H$5:$H$98,MATCH($B21,'Liste des ingrédients'!$B$5:$B$98,0)),0)) -> 4.5 | K21: =IF($B21="",0,H21*J21) -> 27 | N21: =IF($O21="","",13) -> 13 | O21: =IF('Hygiène & entretien'!B20="","",'Hygiène & entretien'!B20) -> Lessive en poudre (machine) | P21: =IF(O21="","",'Hygiène & entretien'!C20&"") -> صابون ماكينة (saboun makina) | Q21: =IF(O21="","",'Hygiène & entretien'!D20&"") -> paquet | R21: =IF(O21="",0,IF('Hygiène & entretien'!E20="Oui",N('Hygiène & entretien'!F20),0)) -> 1 | T21: =IF(S21="",R21,S21) -> 1 | U21: =IF(O21="",0,N('Hygiène & entretien'!G20)) -> 21.79 | V21: =T21*U21 -> 21.79
A22: =IF($B22="","",14) -> 14 | B22: =IF(Listes!A14="","",Listes!A14) -> Œufs | C22: =IF($B22="","",IFERROR(INDEX('Liste des ingrédients'!$C$5:$C$98,MATCH($B22,'Liste des ingrédients'!$B$5:$B$98,0)),"")) -> عظم (3dham) | D22: =IF($B22="","",Listes!E14) -> 55 | E22: =IF($B22="","",IF(I22="kg","g",IF(I22="L","ml",I22))) -> œuf | F22: =IF($B22="",0,IF(OR(I22="kg",I22="L"),ROUND(D22/1000,3),ROUNDUP(D22,0))) -> 55 | H22: =IF(G22="",F22,G22) -> 55 | I22: =IF($B22="","",IFERROR(INDEX('Liste des ingrédients'!$G$5:$G$98,MATCH($B22,'Liste des ingrédients'!$B$5:$B$98,0)),"")) -> œuf | J22: =IF($B22="",0,IFERROR(INDEX('Liste des ingrédients'!$H$5:$H$98,MATCH($B22,'Liste des ingrédients'!$B$5:$B$98,0)),0)) -> 0.3 | K22: =IF($B22="",0,H22*J22) -> 16.5 | N22: =IF($O22="","",14) -> 14 | O22: =IF('Hygiène & entretien'!B21="","",'Hygiène & entretien'!B21) -> Éponges | P22: =IF(O22="","",'Hygiène & entretien'!C21&"") -> سفنجة (sfenja) | Q22: =IF(O22="","",'Hygiène & entretien'!D21&"") -> pièce | R22: =IF(O22="",0,IF('Hygiène & entretien'!E21="Oui",N('Hygiène & entretien'!F21),0)) -> 4 | T22: =IF(S22="",R22,S22) -> 4 | U22: =IF(O22="",0,N('Hygiène & entretien'!G21)) -> 0.69 | V22: =T22*U22 -> 2.76
A23: =IF($B23="","",15) -> 15 | B23: =IF(Listes!A15="","",Listes!A15) -> Fromage râpé | C23: =IF($B23="","",IFERROR(INDEX('Liste des ingrédients'!$C$5:$C$98,MATCH($B23,'Liste des ingrédients'!$B$5:$B$98,0)),"")) -> فرماج مرحي (fromej mra7i) | D23: =IF($B23="","",Listes!E15) -> 360 | E23: =IF($B23="","",IF(I23="kg","g",IF(I23="L","ml",I23))) -> g | F23: =IF($B23="",0,IF(OR(I23="kg",I23="L"),ROUND(D23/1000,3),ROUNDUP(D23,0))) -> 0.36 | H23: =IF(G23="",F23,G23) -> 0.36 | I23: =IF($B23="","",IFERROR(INDEX('Liste des ingrédients'!$G$5:$G$98,MATCH($B23,'Liste des ingrédients'!$B$5:$B$98,0)),"")) -> kg | J23: =IF($B23="",0,IFERROR(INDEX('Liste des ingrédients'!$H$5:$H$98,MATCH($B23,'Liste des ingrédients'!$B$5:$B$98,0)),0)) -> 30 | K23: =IF($B23="",0,H23*J23) -> 10.8 | N23: =IF($O23="","",15) -> 15 | O23: =IF('Hygiène & entretien'!B22="","",'Hygiène & entretien'!B22) -> Sacs poubelle 70 L | P23: =IF(O23="","",'Hygiène & entretien'!C22&"") -> ساشيات زبلة (sachiet zebla) | Q23: =IF(O23="","",'Hygiène & entretien'!D22&"") -> rouleau de 10 | R23: =IF(O23="",0,IF('Hygiène & entretien'!E22="Oui",N('Hygiène & entretien'!F22),0)) -> 3 | T23: =IF(S23="",R23,S23) -> 3 | U23: =IF(O23="",0,N('Hygiène & entretien'!G22)) -> 2.15 | V23: =T23*U23 -> 6.45
A24: =IF($B24="","",16) -> 16 | B24: =IF(Listes!A16="","",Listes!A16) -> Pommes de terre | C24: =IF($B24="","",IFERROR(INDEX('Liste des ingrédients'!$C$5:$C$98,MATCH($B24,'Liste des ingrédients'!$B$5:$B$98,0)),"")) -> بطاطا (batata) | D24: =IF($B24="","",Listes!E16) -> 5700 | E24: =IF($B24="","",IF(I24="kg","g",IF(I24="L","ml",I24))) -> g | F24: =IF($B24="",0,IF(OR(I24="kg",I24="L"),ROUND(D24/1000,3),ROUNDUP(D24,0))) -> 5.7 | H24: =IF(G24="",F24,G24) -> 5.7 | I24: =IF($B24="","",IFERROR(INDEX('Liste des ingrédients'!$G$5:$G$98,MATCH($B24,'Liste des ingrédients'!$B$5:$B$98,0)),"")) -> kg | J24: =IF($B24="",0,IFERROR(INDEX('Liste des ingrédients'!$H$5:$H$98,MATCH($B24,'Liste des ingrédients'!$B$5:$B$98,0)),0)) -> 2.5 | K24: =IF($B24="",0,H24*J24) -> 14.25 | N24: =IF($O24="","",16) -> 16 | O24: =IF('Hygiène & entretien'!B23="","",'Hygiène & entretien'!B23) -> Serviettes de table | P24: =IF(O24="","",'Hygiène & entretien'!C23&"") -> محارم (m7arem) | Q24: =IF(O24="","",'Hygiène & entretien'!D23&"") -> paquet de 90 | R24: =IF(O24="",0,IF('Hygiène & entretien'!E23="Oui",N('Hygiène & entretien'!F23),0)) -> 1 | T24: =IF(S24="",R24,S24) -> 1 | U24: =IF(O24="",0,N('Hygiène & entretien'!G23)) -> 3.06 | V24: =T24*U24 -> 3.06
A25: =IF($B25="","",17) -> 17 | B25: =IF(Listes!A17="","",Listes!A17) -> Tomates | C25: =IF($B25="","",IFERROR(INDEX('Liste des ingrédients'!$C$5:$C$98,MATCH($B25,'Liste des ingrédients'!$B$5:$B$98,0)),"")) -> طماطم (tmatem) | D25: =IF($B25="","",Listes!E17) -> 4650 | E25: =IF($B25="","",IF(I25="kg","g",IF(I25="L","ml",I25))) -> g | F25: =IF($B25="",0,IF(OR(I25="kg",I25="L"),ROUND(D25/1000,3),ROUNDUP(D25,0))) -> 4.65 | H25: =IF(G25="",F25,G25) -> 4.65 | I25: =IF($B25="","",IFERROR(INDEX('Liste des ingrédients'!$G$5:$G$98,MATCH($B25,'Liste des ingrédients'!$B$5:$B$98,0)),"")) -> kg | J25: =IF($B25="",0,IFERROR(INDEX('Liste des ingrédients'!$H$5:$H$98,MATCH($B25,'Liste des ingrédients'!$B$5:$B$98,0)),0)) -> 2 | K25: =IF($B25="",0,H25*J25) -> 9.3 | N25: =IF($O25="","",17) | O25: =IF('Hygiène & entretien'!B26="","",'Hygiène & entretien'!B26) | P25: =IF(O25="","",'Hygiène & entretien'!C26&"") | Q25: =IF(O25="","",'Hygiène & entretien'!D26&"") | R25: =IF(O25="",0,IF('Hygiène & entretien'!E26="Oui",N('Hygiène & entretien'!F26),0)) -> 0 | T25: =IF(S25="",R25,S25) -> 0 | U25: =IF(O25="",0,N('Hygiène & entretien'!G26)) -> 0 | V25: =T25*U25 -> 0
A26: =IF($B26="","",18) -> 18 | B26: =IF(Listes!A18="","",Listes!A18) -> Oignons | C26: =IF($B26="","",IFERROR(INDEX('Liste des ingrédients'!$C$5:$C$98,MATCH($B26,'Liste des ingrédients'!$B$5:$B$98,0)),"")) -> بصل (bsal) | D26: =IF($B26="","",Listes!E18) -> 2500 | E26: =IF($B26="","",IF(I26="kg","g",IF(I26="L","ml",I26))) -> g | F26: =IF($B26="",0,IF(OR(I26="kg",I26="L"),ROUND(D26/1000,3),ROUNDUP(D26,0))) -> 2.5 | H26: =IF(G26="",F26,G26) -> 2.5 | I26: =IF($B26="","",IFERROR(INDEX('Liste des ingrédients'!$G$5:$G$98,MATCH($B26,'Liste des ingrédients'!$B$5:$B$98,0)),"")) -> kg | J26: =IF($B26="",0,IFERROR(INDEX('Liste des ingrédients'!$H$5:$H$98,MATCH($B26,'Liste des ingrédients'!$B$5:$B$98,0)),0)) -> 1.2 | K26: =IF($B26="",0,H26*J26) -> 3 | N26: =IF($O26="","",18) | O26: =IF('Hygiène & entretien'!B27="","",'Hygiène & entretien'!B27) | P26: =IF(O26="","",'Hygiène & entretien'!C27&"") | Q26: =IF(O26="","",'Hygiène & entretien'!D27&"") | R26: =IF(O26="",0,IF('Hygiène & entretien'!E27="Oui",N('Hygiène & entretien'!F27),0)) -> 0 | T26: =IF(S26="",R26,S26) -> 0 | U26: =IF(O26="",0,N('Hygiène & entretien'!G27)) -> 0 | V26: =T26*U26 -> 0
A27: =IF($B27="","",19) -> 19 | B27: =IF(Listes!A19="","",Listes!A19) -> Ail | C27: =IF($B27="","",IFERROR(INDEX('Liste des ingrédients'!$C$5:$C$98,MATCH($B27,'Liste des ingrédients'!$B$5:$B$98,0)),"")) -> ثوم (thoum) | D27: =IF($B27="","",Listes!E19) -> 370 | E27: =IF($B27="","",IF(I27="kg","g",IF(I27="L","ml",I27))) -> g | F27: =IF($B27="",0,IF(OR(I27="kg",I27="L"),ROUND(D27/1000,3),ROUNDUP(D27,0))) -> 0.37 | H27: =IF(G27="",F27,G27) -> 0.37 | I27: =IF($B27="","",IFERROR(INDEX('Liste des ingrédients'!$G$5:$G$98,MATCH($B27,'Liste des ingrédients'!$B$5:$B$98,0)),"")) -> kg | J27: =IF($B27="",0,IFERROR(INDEX('Liste des ingrédients'!$H$5:$H$98,MATCH($B27,'Liste des ingrédients'!$B$5:$B$98,0)),0)) -> 15 | K27: =IF($B27="",0,H27*J27) -> 5.55 | N27: =IF($O27="","",19) | O27: =IF('Hygiène & entretien'!B28="","",'Hygiène & entretien'!B28) | P27: =IF(O27="","",'Hygiène & entretien'!C28&"") | Q27: =IF(O27="","",'Hygiène & entretien'!D28&"") | R27: =IF(O27="",0,IF('Hygiène & entretien'!E28="Oui",N('Hygiène & entretien'!F28),0)) -> 0 | T27: =IF(S27="",R27,S27) -> 0 | U27: =IF(O27="",0,N('Hygiène & entretien'!G28)) -> 0 | V27: =T27*U27 -> 0
A28: =IF($B28="","",20) -> 20 | B28: =IF(Listes!A20="","",Listes!A20) -> Carottes | C28: =IF($B28="","",IFERROR(INDEX('Liste des ingrédients'!$C$5:$C$98,MATCH($B28,'Liste des ingrédients'!$B$5:$B$98,0)),"")) -> سفنارية (sfenarya) | D28: =IF($B28="","",Listes!E20) -> 1500 | E28: =IF($B28="","",IF(I28="kg","g",IF(I28="L","ml",I28))) -> g | F28: =IF($B28="",0,IF(OR(I28="kg",I28="L"),ROUND(D28/1000,3),ROUNDUP(D28,0))) -> 1.5 | H28: =IF(G28="",F28,G28) -> 1.5 | I28: =IF($B28="","",IFERROR(INDEX('Liste des ingrédients'!$G$5:$G$98,MATCH($B28,'Liste des ingrédients'!$B$5:$B$98,0)),"")) -> kg | J28: =IF($B28="",0,IFERROR(INDEX('Liste des ingrédients'!$H$5:$H$98,MATCH($B28,'Liste des ingrédients'!$B$5:$B$98,0)),0)) -> 2.5 | K28: =IF($B28="",0,H28*J28) -> 3.75 | N28: =IF($O28="","",20) | O28: =IF('Hygiène & entretien'!B29="","",'Hygiène & entretien'!B29) | P28: =IF(O28="","",'Hygiène & entretien'!C29&"") | Q28: =IF(O28="","",'Hygiène & entretien'!D29&"") | R28: =IF(O28="",0,IF('Hygiène & entretien'!E29="Oui",N('Hygiène & entretien'!F29),0)) -> 0 | T28: =IF(S28="",R28,S28) -> 0 | U28: =IF(O28="",0,N('Hygiène & entretien'!G29)) -> 0 | V28: =T28*U28 -> 0
A29: =IF($B29="","",21) -> 21 | B29: =IF(Listes!A21="","",Listes!A21) -> Courgettes | C29: =IF($B29="","",IFERROR(INDEX('Liste des ingrédients'!$C$5:$C$98,MATCH($B29,'Liste des ingrédients'!$B$5:$B$98,0)),"")) -> قرع (gar3) | D29: =IF($B29="","",Listes!E21) -> 1800 | E29: =IF($B29="","",IF(I29="kg","g",IF(I29="L","ml",I29))) -> g | F29: =IF($B29="",0,IF(OR(I29="kg",I29="L"),ROUND(D29/1000,3),ROUNDUP(D29,0))) -> 1.8 | H29: =IF(G29="",F29,G29) -> 1.8 | I29: =IF($B29="","",IFERROR(INDEX('Liste des ingrédients'!$G$5:$G$98,MATCH($B29,'Liste des ingrédients'!$B$5:$B$98,0)),"")) -> kg | J29: =IF($B29="",0,IFERROR(INDEX('Liste des ingrédients'!$H$5:$H$98,MATCH($B29,'Liste des ingrédients'!$B$5:$B$98,0)),0)) -> 2 | K29: =IF($B29="",0,H29*J29) -> 3.6 | N29: =IF($O29="","",21) | O29: =IF('Hygiène & entretien'!B30="","",'Hygiène & entretien'!B30) | P29: =IF(O29="","",'Hygiène & entretien'!C30&"") | Q29: =IF(O29="","",'Hygiène & entretien'!D30&"") | R29: =IF(O29="",0,IF('Hygiène & entretien'!E30="Oui",N('Hygiène & entretien'!F30),0)) -> 0 | T29: =IF(S29="",R29,S29) -> 0 | U29: =IF(O29="",0,N('Hygiène & entretien'!G30)) -> 0 | V29: =T29*U29 -> 0
A30: =IF($B30="","",22) -> 22 | B30: =IF(Listes!A22="","",Listes!A22) -> Poivrons | C30: =IF($B30="","",IFERROR(INDEX('Liste des ingrédients'!$C$5:$C$98,MATCH($B30,'Liste des ingrédients'!$B$5:$B$98,0)),"")) -> فلفل حلو (felfel 7lou) | D30: =IF($B30="","",Listes!E22) -> 1600 | E30: =IF($B30="","",IF(I30="kg","g",IF(I30="L","ml",I30))) -> g | F30: =IF($B30="",0,IF(OR(I30="kg",I30="L"),ROUND(D30/1000,3),ROUNDUP(D30,0))) -> 1.6 | H30: =IF(G30="",F30,G30) -> 1.6 | I30: =IF($B30="","",IFERROR(INDEX('Liste des ingrédients'!$G$5:$G$98,MATCH($B30,'Liste des ingrédients'!$B$5:$B$98,0)),"")) -> kg | J30: =IF($B30="",0,IFERROR(INDEX('Liste des ingrédients'!$H$5:$H$98,MATCH($B30,'Liste des ingrédients'!$B$5:$B$98,0)),0)) -> 2.5 | K30: =IF($B30="",0,H30*J30) -> 4 | N30: =IF($O30="","",22) | O30: =IF('Hygiène & entretien'!B31="","",'Hygiène & entretien'!B31) | P30: =IF(O30="","",'Hygiène & entretien'!C31&"") | Q30: =IF(O30="","",'Hygiène & entretien'!D31&"") | R30: =IF(O30="",0,IF('Hygiène & entretien'!E31="Oui",N('Hygiène & entretien'!F31),0)) -> 0 | T30: =IF(S30="",R30,S30) -> 0 | U30: =IF(O30="",0,N('Hygiène & entretien'!G31)) -> 0 | V30: =T30*U30 -> 0
A31: =IF($B31="","",23) -> 23 | B31: =IF(Listes!A23="","",Listes!A23) -> Piments verts | C31: =IF($B31="","",IFERROR(INDEX('Liste des ingrédients'!$C$5:$C$98,MATCH($B31,'Liste des ingrédients'!$B$5:$B$98,0)),"")) -> فلفل أخضر (felfel akhdhar) | D31: =IF($B31="","",Listes!E23) -> 480 | E31: =IF($B31="","",IF(I31="kg","g",IF(I31="L","ml",I31))) -> g | F31: =IF($B31="",0,IF(OR(I31="kg",I31="L"),ROUND(D31/1000,3),ROUNDUP(D31,0))) -> 0.48 | H31: =IF(G31="",F31,G31) -> 0.48 | I31: =IF($B31="","",IFERROR(INDEX('Liste des ingrédients'!$G$5:$G$98,MATCH($B31,'Liste des ingrédients'!$B$5:$B$98,0)),"")) -> kg | J31: =IF($B31="",0,IFERROR(INDEX('Liste des ingrédients'!$H$5:$H$98,MATCH($B31,'Liste des ingrédients'!$B$5:$B$98,0)),0)) -> 2.5 | K31: =IF($B31="",0,H31*J31) -> 1.2 | N31: =IF($O31="","",23) | O31: =IF('Hygiène & entretien'!B32="","",'Hygiène & entretien'!B32) | P31: =IF(O31="","",'Hygiène & entretien'!C32&"") | Q31: =IF(O31="","",'Hygiène & entretien'!D32&"") | R31: =IF(O31="",0,IF('Hygiène & entretien'!E32="Oui",N('Hygiène & entretien'!F32),0)) -> 0 | T31: =IF(S31="",R31,S31) -> 0 | U31: =IF(O31="",0,N('Hygiène & entretien'!G32)) -> 0 | V31: =T31*U31 -> 0
A32: =IF($B32="","",24) -> 24 | B32: =IF(Listes!A24="","",Listes!A24) -> Piments forts | C32: =IF($B32="","",IFERROR(INDEX('Liste des ingrédients'!$C$5:$C$98,MATCH($B32,'Liste des ingrédients'!$B$5:$B$98,0)),"")) -> فلفل حار (felfel 7arr) | D32: =IF($B32="","",Listes!E24) -> 65 | E32: =IF($B32="","",IF(I32="kg","g",IF(I32="L","ml",I32))) -> g | F32: =IF($B32="",0,IF(OR(I32="kg",I32="L"),ROUND(D32/1000,3),ROUNDUP(D32,0))) -> 0.065 | H32: =IF(G32="",F32,G32) -> 0.065 | I32: =IF($B32="","",IFERROR(INDEX('Liste des ingrédients'!$G$5:$G$98,MATCH($B32,'Liste des ingrédients'!$B$5:$B$98,0)),"")) -> kg | J32: =IF($B32="",0,IFERROR(INDEX('Liste des ingrédients'!$H$5:$H$98,MATCH($B32,'Liste des ingrédients'!$B$5:$B$98,0)),0)) -> 3.3 | K32: =IF($B32="",0,H32*J32) -> 0.2145 | N32: =IF($O32="","",24) | O32: =IF('Hygiène & entretien'!B33="","",'Hygiène & entretien'!B33) | P32: =IF(O32="","",'Hygiène & entretien'!C33&"") | Q32: =IF(O32="","",'Hygiène & entretien'!D33&"") | R32: =IF(O32="",0,IF('Hygiène & entretien'!E33="Oui",N('Hygiène & entretien'!F33),0)) -> 0 | T32: =IF(S32="",R32,S32) -> 0 | U32: =IF(O32="",0,N('Hygiène & entretien'!G33)) -> 0 | V32: =T32*U32 -> 0
A33: =IF($B33="","",25) -> 25 | B33: =IF(Listes!A25="","",Listes!A25) -> Citrouille / potiron | C33: =IF($B33="","",IFERROR(INDEX('Liste des ingrédients'!$C$5:$C$98,MATCH($B33,'Liste des ingrédients'!$B$5:$B$98,0)),"")) -> كابوية (kabouya) | D33: =IF($B33="","",Listes!E25) -> 900 | E33: =IF($B33="","",IF(I33="kg","g",IF(I33="L","ml",I33))) -> g | F33: =IF($B33="",0,IF(OR(I33="kg",I33="L"),ROUND(D33/1000,3),ROUNDUP(D33,0))) -> 0.9 | H33: =IF(G33="",F33,G33) -> 0.9 | I33: =IF($B33="","",IFERROR(INDEX('Liste des ingrédients'!$G$5:$G$98,MATCH($B33,'Liste des ingrédients'!$B$5:$B$98,0)),"")) -> kg | J33: =IF($B33="",0,IFERROR(INDEX('Liste des ingrédients'!$H$5:$H$98,MATCH($B33,'Liste des ingrédients'!$B$5:$B$98,0)),0)) -> 1.5 | K33: =IF($B33="",0,H33*J33) -> 1.35 | N33: =IF($O33="","",25) | O33: =IF('Hygiène & entretien'!B34="","",'Hygiène & entretien'!B34) | P33: =IF(O33="","",'Hygiène & entretien'!C34&"") | Q33: =IF(O33="","",'Hygiène & entretien'!D34&"") | R33: =IF(O33="",0,IF('Hygiène & entretien'!E34="Oui",N('Hygiène & entretien'!F34),0)) -> 0 | T33: =IF(S33="",R33,S33) -> 0 | U33: =IF(O33="",0,N('Hygiène & entretien'!G34)) -> 0 | V33: =T33*U33 -> 0
A34: =IF($B34="","",26) -> 26 | B34: =IF(Listes!A26="","",Listes!A26) -> Concombres | C34: =IF($B34="","",IFERROR(INDEX('Liste des ingrédients'!$C$5:$C$98,MATCH($B34,'Liste des ingrédients'!$B$5:$B$98,0)),"")) -> فقوس (fagous) | D34: =IF($B34="","",Listes!E26) -> 1600 | E34: =IF($B34="","",IF(I34="kg","g",IF(I34="L","ml",I34))) -> g | F34: =IF($B34="",0,IF(OR(I34="kg",I34="L"),ROUND(D34/1000,3),ROUNDUP(D34,0))) -> 1.6 | H34: =IF(G34="",F34,G34) -> 1.6 | I34: =IF($B34="","",IFERROR(INDEX('Liste des ingrédients'!$G$5:$G$98,MATCH($B34,'Liste des ingrédients'!$B$5:$B$98,0)),"")) -> kg | J34: =IF($B34="",0,IFERROR(INDEX('Liste des ingrédients'!$H$5:$H$98,MATCH($B34,'Liste des ingrédients'!$B$5:$B$98,0)),0)) -> 2.5 | K34: =IF($B34="",0,H34*J34) -> 4 | N34: =IF($O34="","",26) | O34: =IF('Hygiène & entretien'!B35="","",'Hygiène & entretien'!B35) | P34: =IF(O34="","",'Hygiène & entretien'!C35&"") | Q34: =IF(O34="","",'Hygiène & entretien'!D35&"") | R34: =IF(O34="",0,IF('Hygiène & entretien'!E35="Oui",N('Hygiène & entretien'!F35),0)) -> 0 | T34: =IF(S34="",R34,S34) -> 0 | U34: =IF(O34="",0,N('Hygiène & entretien'!G35)) -> 0 | V34: =T34*U34 -> 0
A35: =IF($B35="","",27) -> 27 | B35: =IF(Listes!A27="","",Listes!A27) -> Laitues | C35: =IF($B35="","",IFERROR(INDEX('Liste des ingrédients'!$C$5:$C$98,MATCH($B35,'Liste des ingrédients'!$B$5:$B$98,0)),"")) -> خص (khass) | D35: =IF($B35="","",Listes!E27) -> 4 | E35: =IF($B35="","",IF(I35="kg","g",IF(I35="L","ml",I35))) -> pièce | F35: =IF($B35="",0,IF(OR(I35="kg",I35="L"),ROUND(D35/1000,3),ROUNDUP(D35,0))) -> 4 | H35: =IF(G35="",F35,G35) -> 4 | I35: =IF($B35="","",IFERROR(INDEX('Liste des ingrédients'!$G$5:$G$98,MATCH($B35,'Liste des ingrédients'!$B$5:$B$98,0)),"")) -> pièce | J35: =IF($B35="",0,IFERROR(INDEX('Liste des ingrédients'!$H$5:$H$98,MATCH($B35,'Liste des ingrédients'!$B$5:$B$98,0)),0)) -> 1 | K35: =IF($B35="",0,H35*J35) -> 4
A36: =IF($B36="","",28) -> 28 | B36: =IF(Listes!A28="","",Listes!A28) -> Épinards (ou blettes) | C36: =IF($B36="","",IFERROR(INDEX('Liste des ingrédients'!$C$5:$C$98,MATCH($B36,'Liste des ingrédients'!$B$5:$B$98,0)),"")) -> سبناخ (sbenekh) / سلق (selg) | D36: =IF($B36="","",Listes!E28) -> 600 | E36: =IF($B36="","",IF(I36="kg","g",IF(I36="L","ml",I36))) -> g | F36: =IF($B36="",0,IF(OR(I36="kg",I36="L"),ROUND(D36/1000,3),ROUNDUP(D36,0))) -> 0.6 | H36: =IF(G36="",F36,G36) -> 0.6 | I36: =IF($B36="","",IFERROR(INDEX('Liste des ingrédients'!$G$5:$G$98,MATCH($B36,'Liste des ingrédients'!$B$5:$B$98,0)),"")) -> kg | J36: =IF($B36="",0,IFERROR(INDEX('Liste des ingrédients'!$H$5:$H$98,MATCH($B36,'Liste des ingrédients'!$B$5:$B$98,0)),0)) -> 4 | K36: =IF($B36="",0,H36*J36) -> 2.4
A37: =IF($B37="","",29) -> 29 | B37: =IF(Listes!A29="","",Listes!A29) -> Petits pois | C37: =IF($B37="","",IFERROR(INDEX('Liste des ingrédients'!$C$5:$C$98,MATCH($B37,'Liste des ingrédients'!$B$5:$B$98,0)),"")) -> جلبانة (jelbana) | D37: =IF($B37="","",Listes!E29) -> 700 | E37: =IF($B37="","",IF(I37="kg","g",IF(I37="L","ml",I37))) -> g | F37: =IF($B37="",0,IF(OR(I37="kg",I37="L"),ROUND(D37/1000,3),ROUNDUP(D37,0))) -> 0.7 | H37: =IF(G37="",F37,G37) -> 0.7 | I37: =IF($B37="","",IFERROR(INDEX('Liste des ingrédients'!$G$5:$G$98,MATCH($B37,'Liste des ingrédients'!$B$5:$B$98,0)),"")) -> kg | J37: =IF($B37="",0,IFERROR(INDEX('Liste des ingrédients'!$H$5:$H$98,MATCH($B37,'Liste des ingrédients'!$B$5:$B$98,0)),0)) -> 3.4 | K37: =IF($B37="",0,H37*J37) -> 2.38
A38: =IF($B38="","",30) -> 30 | B38: =IF(Listes!A30="","",Listes!A30) -> Céleri | C38: =IF($B38="","",IFERROR(INDEX('Liste des ingrédients'!$C$5:$C$98,MATCH($B38,'Liste des ingrédients'!$B$5:$B$98,0)),"")) -> كرافس (krafes) | D38: =IF($B38="","",Listes!E30) -> 1 | E38: =IF($B38="","",IF(I38="kg","g",IF(I38="L","ml",I38))) -> botte | F38: =IF($B38="",0,IF(OR(I38="kg",I38="L"),ROUND(D38/1000,3),ROUNDUP(D38,0))) -> 1 | H38: =IF(G38="",F38,G38) -> 1 | I38: =IF($B38="","",IFERROR(INDEX('Liste des ingrédients'!$G$5:$G$98,MATCH($B38,'Liste des ingrédients'!$B$5:$B$98,0)),"")) -> botte | J38: =IF($B38="",0,IFERROR(INDEX('Liste des ingrédients'!$H$5:$H$98,MATCH($B38,'Liste des ingrédients'!$B$5:$B$98,0)),0)) -> 1 | K38: =IF($B38="",0,H38*J38) -> 1
A39: =IF($B39="","",31) -> 31 | B39: =IF(Listes!A31="","",Listes!A31) -> Persil | C39: =IF($B39="","",IFERROR(INDEX('Liste des ingrédients'!$C$5:$C$98,MATCH($B39,'Liste des ingrédients'!$B$5:$B$98,0)),"")) -> معدنوس (ma3dnous) | D39: =IF($B39="","",Listes!E31) -> 5 | E39: =IF($B39="","",IF(I39="kg","g",IF(I39="L","ml",I39))) -> botte | F39: =IF($B39="",0,IF(OR(I39="kg",I39="L"),ROUND(D39/1000,3),ROUNDUP(D39,0))) -> 5 | H39: =IF(G39="",F39,G39) -> 5 | I39: =IF($B39="","",IFERROR(INDEX('Liste des ingrédients'!$G$5:$G$98,MATCH($B39,'Liste des ingrédients'!$B$5:$B$98,0)),"")) -> botte | J39: =IF($B39="",0,IFERROR(INDEX('Liste des ingrédients'!$H$5:$H$98,MATCH($B39,'Liste des ingrédients'!$B$5:$B$98,0)),0)) -> 0.8 | K39: =IF($B39="",0,H39*J39) -> 4
A40: =IF($B40="","",32) -> 32 | B40: =IF(Listes!A32="","",Listes!A32) -> Romarin ou thym | C40: =IF($B40="","",IFERROR(INDEX('Liste des ingrédients'!$C$5:$C$98,MATCH($B40,'Liste des ingrédients'!$B$5:$B$98,0)),"")) -> إكليل (iklil) / زعتر (za3tar) | D40: =IF($B40="","",Listes!E32) -> 1 | E40: =IF($B40="","",IF(I40="kg","g",IF(I40="L","ml",I40))) -> botte | F40: =IF($B40="",0,IF(OR(I40="kg",I40="L"),ROUND(D40/1000,3),ROUNDUP(D40,0))) -> 1 | H40: =IF(G40="",F40,G40) -> 1 | I40: =IF($B40="","",IFERROR(INDEX('Liste des ingrédients'!$G$5:$G$98,MATCH($B40,'Liste des ingrédients'!$B$5:$B$98,0)),"")) -> botte | J40: =IF($B40="",0,IFERROR(INDEX('Liste des ingrédients'!$H$5:$H$98,MATCH($B40,'Liste des ingrédients'!$B$5:$B$98,0)),0)) -> 1 | K40: =IF($B40="",0,H40*J40) -> 1
A41: =IF($B41="","",33) -> 33 | B41: =IF(Listes!A33="","",Listes!A33) -> Citrons | C41: =IF($B41="","",IFERROR(INDEX('Liste des ingrédients'!$C$5:$C$98,MATCH($B41,'Liste des ingrédients'!$B$5:$B$98,0)),"")) -> قارص (gares) | D41: =IF($B41="","",Listes!E33) -> 1500 | E41: =IF($B41="","",IF(I41="kg","g",IF(I41="L","ml",I41))) -> g | F41: =IF($B41="",0,IF(OR(I41="kg",I41="L"),ROUND(D41/1000,3),ROUNDUP(D41,0))) -> 1.5 | H41: =IF(G41="",F41,G41) -> 1.5 | I41: =IF($B41="","",IFERROR(INDEX('Liste des ingrédients'!$G$5:$G$98,MATCH($B41,'Liste des ingrédients'!$B$5:$B$98,0)),"")) -> kg | J41: =IF($B41="",0,IFERROR(INDEX('Liste des ingrédients'!$H$5:$H$98,MATCH($B41,'Liste des ingrédients'!$B$5:$B$98,0)),0)) -> 3 | K41: =IF($B41="",0,H41*J41) -> 4.5
...

Sheet Plats
A1: Plats à préparer – coût automatique
A2: Mettez « Non » dans « Préparer ? » pour retirer un plat. Pour AJOUTER un plat : tapez le jour, le repas et le nom dans une ligne jaune en bas, puis ajoutez ses ingrédients dans l'onglet « Ingrédients par plat » (lignes vides en bas, choisissez le plat dans la liste).
A4: Jour | B4: Repas | C4: Plat | D4: Préparer ? | E4: Nb d'ingrédients | F4: Coût du plat (DT) | G4: Coût par personne (DT) | H4: Coût retenu (DT)
A5: Jour 1 | B5: Déjeuner | C5: Couscous au poisson | D5: Oui | E5: =IF(C5="","",COUNTIF('Ingrédients par plat'!$A$5:$A$596,$I5)) -> 17 | F5: =SUMIF('Ingrédients par plat'!$A$5:$A$596,$I5,'Ingrédients par plat'!$G$5:$G$596) -> 29.5996 | G5: =F5/4 -> 7.3999 | H5: =IF(AND(D5="Oui",C5<>""),F5,0) -> 29.5996 | I5: =IF(C5="","",A5&" "&B5&" – "&C5) -> Jour 1 Déjeuner – Couscous au poisson
A6: Jour 1 | B6: Dîner | C6: Salade méchouia + thon, œufs + pain maison | D6: Oui | E6: =IF(C6="","",COUNTIF('Ingrédients par plat'!$A$5:$A$596,$I6)) -> 13 | F6: =SUMIF('Ingrédients par plat'!$A$5:$A$596,$I6,'Ingrédients par plat'!$G$5:$G$596) -> 10.6806 | G6: =F6/4 -> 2.67015 | H6: =IF(AND(D6="Oui",C6<>""),F6,0) -> 10.6806 | I6: =IF(C6="","",A6&" "&B6&" – "&C6) -> Jour 1 Dîner – Salade méchouia + thon, œufs + pain maison
A7: Jour 2 | B7: Déjeuner | C7: Tajine tunisien au poulet | D7: Oui | E7: =IF(C7="","",COUNTIF('Ingrédients par plat'!$A$5:$A$596,$I7)) -> 12 | F7: =SUMIF('Ingrédients par plat'!$A$5:$A$596,$I7,'Ingrédients par plat'!$G$5:$G$596) -> 19.6193 | G7: =F7/4 -> 4.904825 | H7: =IF(AND(D7="Oui",C7<>""),F7,0) -> 19.6193 | I7: =IF(C7="","",A7&" "&B7&" – "&C7) -> Jour 2 Déjeuner – Tajine tunisien au poulet
A8: Jour 2 | B8: Dîner | C8: Chorba frik | D8: Oui | E8: =IF(C8="","",COUNTIF('Ingrédients par plat'!$A$5:$A$596,$I8)) -> 17 | F8: =SUMIF('Ingrédients par plat'!$A$5:$A$596,$I8,'Ingrédients par plat'!$G$5:$G$596) -> 28.6197 | G8: =F8/4 -> 7.154925 | H8: =IF(AND(D8="Oui",C8<>""),F8,0) -> 28.6197 | I8: =IF(C8="","",A8&" "&B8&" – "&C8) -> Jour 2 Dîner – Chorba frik
A9: Jour 3 | B9: Déjeuner | C9: Marqa jelbana bel djedj | D9: Oui | E9: =IF(C9="","",COUNTIF('Ingrédients par plat'!$A$5:$A$596,$I9)) -> 9 | F9: =SUMIF('Ingrédients par plat'!$A$5:$A$596,$I9,'Ingrédients par plat'!$G$5:$G$596) -> 18.3797 | G9: =F9/4 -> 4.594925 | H9: =IF(AND(D9="Oui",C9<>""),F9,0) -> 18.3797 | I9: =IF(C9="","",A9&" "&B9&" – "&C9) -> Jour 3 Déjeuner – Marqa jelbana bel djedj
A10: Jour 3 | B10: Dîner | C10: Ojja merguez + pain | D10: Oui | E10: =IF(C10="","",COUNTIF('Ingrédients par plat'!$A$5:$A$596,$I10)) -> 13 | F10: =SUMIF('Ingrédients par plat'!$A$5:$A$596,$I10,'Ingrédients par plat'!$G$5:$G$596) -> 25.2068 | G10: =F10/4 -> 6.3017 | H10: =IF(AND(D10="Oui",C10<>""),F10,0) -> 25.2068 | I10: =IF(C10="","",A10&" "&B10&" – "&C10) -> Jour 3 Dîner – Ojja merguez + pain
A11: Jour 4 | B11: Déjeuner | C11: Spaghetti tunisien | D11: Oui | E11: =IF(C11="","",COUNTIF('Ingrédients par plat'!$A$5:$A$596,$I11)) -> 12 | F11: =SUMIF('Ingrédients par plat'!$A$5:$A$596,$I11,'Ingrédients par plat'!$G$5:$G$596) -> 11.3297 | G11: =F11/4 -> 2.832425 | H11: =IF(AND(D11="Oui",C11<>""),F11,0) -> 11.3297 | I11: =IF(C11="","",A11&" "&B11&" – "&C11) -> Jour 4 Déjeuner – Spaghetti tunisien
A12: Jour 4 | B12: Dîner | C12: Bricks au thon + salade verte | D12: Oui | E12: =IF(C12="","",COUNTIF('Ingrédients par plat'!$A$5:$A$596,$I12)) -> 14 | F12: =SUMIF('Ingrédients par plat'!$A$5:$A$596,$I12,'Ingrédients par plat'!$G$5:$G$596) -> 19.4393 | G12: =F12/4 -> 4.859825 | H12: =IF(AND(D12="Oui",C12<>""),F12,0) -> 19.4393 | I12: =IF(C12="","",A12&" "&B12&" – "&C12) -> Jour 4 Dîner – Bricks au thon + salade verte
A13: Jour 5 | B13: Déjeuner | C13: Mloukhia | D13: Oui | E13: =IF(C13="","",COUNTIF('Ingrédients par plat'!$A$5:$A$596,$I13)) -> 10 | F13: =SUMIF('Ingrédients par plat'!$A$5:$A$596,$I13,'Ingrédients par plat'!$G$5:$G$596) -> 45.9431 | G13: =F13/4 -> 11.485775 | H13: =IF(AND(D13="Oui",C13<>""),F13,0) -> 45.9431 | I13: =IF(C13="","",A13&" "&B13&" – "&C13) -> Jour 5 Déjeuner – Mloukhia
A14: Jour 5 | B14: Dîner | C14: Chorba langues d'oiseaux + salade tunisienne | D14: Oui | E14: =IF(C14="","",COUNTIF('Ingrédients par plat'!$A$5:$A$596,$I14)) -> 17 | F14: =SUMIF('Ingrédients par plat'!$A$5:$A$596,$I14,'Ingrédients par plat'!$G$5:$G$596) -> 17.122 | G14: =F14/4 -> 4.2805 | H14: =IF(AND(D14="Oui",C14<>""),F14,0) -> 17.122 | I14: =IF(C14="","",A14&" "&B14&" – "&C14) -> Jour 5 Dîner – Chorba langues d'oiseaux + salade tunisienne
A15: Jour 6 | B15: Déjeuner | C15: Marqa loubya bel djedj | D15: Oui | E15: =IF(C15="","",COUNTIF('Ingrédients par plat'!$A$5:$A$596,$I15)) -> 13 | F15: =SUMIF('Ingrédients par plat'!$A$5:$A$596,$I15,'Ingrédients par plat'!$G$5:$G$596) -> 18.9202 | G15: =F15/4 -> 4.73005 | H15: =IF(AND(D15="Oui",C15<>""),F15,0) -> 18.9202 | I15: =IF(C15="","",A15&" "&B15&" – "&C15) -> Jour 6 Déjeuner – Marqa loubya bel djedj
A16: Jour 6 | B16: Dîner | C16: Kefteji | D16: Oui | E16: =IF(C16="","",COUNTIF('Ingrédients par plat'!$A$5:$A$596,$I16)) -> 13 | F16: =SUMIF('Ingrédients par plat'!$A$5:$A$596,$I16,'Ingrédients par plat'!$G$5:$G$596) -> 8.8573 | G16: =F16/4 -> 2.214325 | H16: =IF(AND(D16="Oui",C16<>""),F16,0) -> 8.8573 | I16: =IF(C16="","",A16&" "&B16&" – "&C16) -> Jour 6 Dîner – Kefteji
... A33: Jour 1 à 14 | B33: Dessert | C33: Fruits de saison (1 portion par personne et par jour) | D33: Oui | E33: =IF(C33="","",COUNTIF('Ingrédients par plat'!$A$5:$A$596,$I33)) -> 5 | F33: =SUMIF('Ingrédients par plat'!$A$5:$A$596,$I33,'Ingrédients par plat'!$G$5:$G$596) -> 48.92 | G33: =F33/4 -> 12.23 | H33: =IF(AND(D33="Oui",C33<>""),F33,0) -> 48.92 | I33: =IF(C33="","",A33&" "&B33&" – "&C33) -> Jour 1 à 14 Dessert – Fruits de saison (1 portion par personne et par jour)
D34: Oui | E34: =IF(C34="","",COUNTIF('Ingrédients par plat'!$A$5:$A$596,$I34)) | F34: =SUMIF('Ingrédients par plat'!$A$5:$A$596,$I34,'Ingrédients par plat'!$G$5:$G$596) -> 0 | G34: =F34/4 -> 0 | H34: =IF(AND(D34="Oui",C34<>""),F34,0) -> 0 | I34: =IF(C34="","",A34&" "&B34&" – "&C34)
D35: Oui | E35: =IF(C35="","",COUNTIF('Ingrédients par plat'!$A$5:$A$596,$I35)) | F35: =SUMIF('Ingrédients par plat'!$A$5:$A$596,$I35,'Ingrédients par plat'!$G$5:$G$596) -> 0 | G35: =F35/4 -> 0 | H35: =IF(AND(D35="Oui",C35<>""),F35,0) -> 0 | I35: =IF(C35="","",A35&" "&B35&" – "&C35)
D36: Oui | E36: =IF(C36="","",COUNTIF('Ingrédients par plat'!$A$5:$A$596,$I36)) | F36: =SUMIF('Ingrédients par plat'!$A$5:$A$596,$I36,'Ingrédients par plat'!$G$5:$G$596) -> 0 | G36: =F36/4 -> 0 | H36: =IF(AND(D36="Oui",C36<>""),F36,0) -> 0 | I36: =IF(C36="","",A36&" "&B36&" – "&C36)
D37: Oui | E37: =IF(C37="","",COUNTIF('Ingrédients par plat'!$A$5:$A$596,$I37)) | F37: =SUMIF('Ingrédients par plat'!$A$5:$A$596,$I37,'Ingrédients par plat'!$G$5:$G$596) -> 0 | G37: =F37/4 -> 0 | H37: =IF(AND(D37="Oui",C37<>""),F37,0) -> 0 | I37: =IF(C37="","",A37&" "&B37&" – "&C37)
D38: Oui | E38: =IF(C38="","",COUNTIF('Ingrédients par plat'!$A$5:$A$596,$I38)) | F38: =SUMIF('Ingrédients par plat'!$A$5:$A$596,$I38,'Ingrédients par plat'!$G$5:$G$596) -> 0 | G38: =F38/4 -> 0 | H38: =IF(AND(D38="Oui",C38<>""),F38,0) -> 0 | I38: =IF(C38="","",A38&" "&B38&" – "&C38)
D39: Oui | E39: =IF(C39="","",COUNTIF('Ingrédients par plat'!$A$5:$A$596,$I39)) | F39: =SUMIF('Ingrédients par plat'!$A$5:$A$596,$I39,'Ingrédients par plat'!$G$5:$G$596) -> 0 | G39: =F39/4 -> 0 | H39: =IF(AND(D39="Oui",C39<>""),F39,0) -> 0 | I39: =IF(C39="","",A39&" "&B39&" – "&C39)
D40: Oui | E40: =IF(C40="","",COUNTIF('Ingrédients par plat'!$A$5:$A$596,$I40)) | F40: =SUMIF('Ingrédients par plat'!$A$5:$A$596,$I40,'Ingrédients par plat'!$G$5:$G$596) -> 0 | G40: =F40/4 -> 0 | H40: =IF(AND(D40="Oui",C40<>""),F40,0) -> 0 | I40: =IF(C40="","",A40&" "&B40&" – "&C40)
D41: Oui | E41: =IF(C41="","",COUNTIF('Ingrédients par plat'!$A$5:$A$596,$I41)) | F41: =SUMIF('Ingrédients par plat'!$A$5:$A$596,$I41,'Ingrédients par plat'!$G$5:$G$596) -> 0 | G41: =F41/4 -> 0 | H41: =IF(AND(D41="Oui",C41<>""),F41,0) -> 0 | I41: =IF(C41="","",A41&" "&B41&" – "&C41)
D42: Oui | E42: =IF(C42="","",COUNTIF('Ingrédients par plat'!$A$5:$A$596,$I42)) | F42: =SUMIF('Ingrédients par plat'!$A$5:$A$596,$I42,'Ingrédients par plat'!$G$5:$G$596) -> 0 | G42: =F42/4 -> 0 | H42: =IF(AND(D42="Oui",C42<>""),F42,0) -> 0 | I42: =IF(C42="","",A42&" "&B42&" – "&C42)
D43: Oui | E43: =IF(C43="","",COUNTIF('Ingrédients par plat'!$A$5:$A$596,$I43)) | F43: =SUMIF('Ingrédients par plat'!$A$5:$A$596,$I43,'Ingrédients par plat'!$G$5:$G$596) -> 0 | G43: =F43/4 -> 0 | H43: =IF(AND(D43="Oui",C43<>""),F43,0) -> 0 | I43: =IF(C43="","",A43&" "&B43&" – "&C43)
D44: Oui | E44: =IF(C44="","",COUNTIF('Ingrédients par plat'!$A$5:$A$596,$I44)) | F44: =SUMIF('Ingrédients par plat'!$A$5:$A$596,$I44,'Ingrédients par plat'!$G$5:$G$596) -> 0 | G44: =F44/4 -> 0 | H44: =IF(AND(D44="Oui",C44<>""),F44,0) -> 0 | I44: =IF(C44="","",A44&" "&B44&" – "&C44)
D45: Oui | E45: =IF(C45="","",COUNTIF('Ingrédients par plat'!$A$5:$A$596,$I45)) | F45: =SUMIF('Ingrédients par plat'!$A$5:$A$596,$I45,'Ingrédients par plat'!$G$5:$G$596) -> 0 | G45: =F45/4 -> 0 | H45: =IF(AND(D45="Oui",C45<>""),F45,0) -> 0 | I45: =IF(C45="","",A45&" "&B45&" – "&C45)
... D48: Oui | E48: =IF(C48="","",COUNTIF('Ingrédients par plat'!$A$5:$A$596,$I48)) | F48: =SUMIF('Ingrédients par plat'!$A$5:$A$596,$I48,'Ingrédients par plat'!$G$5:$G$596) -> 0 | G48: =F48/4 -> 0 | H48: =IF(AND(D48="Oui",C48<>""),F48,0) -> 0 | I48: =IF(C48="","",A48&" "&B48&" – "&C48)
C49: TOTAL DES PLATS RETENUS | D49: =COUNTIFS(D5:D48,"Oui",C5:C48,"<>")&" plats" -> 29 plats | H49: =SUM(H5:H48) -> 573.6921
C50: Coût moyen par personne et par jour (14 jours) | H50: =H49/(4*14) -> 10.244502
A52: Note : le coût des plats est calculé au prorata des quantités utilisées. Il est un peu inférieur au total de la liste de courses, qui compte des unités entières (paquets, bottes…) et les fruits.

Sheet Ingrédients par plat
A1: Ingrédients par plat – coût calculé automatiquement
A2: Choisissez l'ingrédient dans la liste déroulante (colonne B) et saisissez la quantité (colonne C, en bleu). L'unité, le prix (repris de l'onglet « Liste des ingrédients ») et le coût se calculent seuls. Lignes vides en bas pour ajouter des ingrédients.
A4: Plat | B4: Ingrédient | C4: Quantité | D4: Unité | E4: Prix unitaire (DT) | F4: Prix par | G4: Coût (DT) | H4: n° (fiche)
A5: Jour 1 Déjeuner – Couscous au poisson | B5: Couscous moyen | C5: 500 | D5: =IF($B5="","",IF(F5="kg","g",IF(F5="L","ml",F5))) -> g | E5: =IF($B5="","",IFERROR(INDEX('Liste des ingrédients'!$H$5:$H$98,MATCH($B5,'Liste des ingrédients'!$B$5:$B$98,0)),0)) -> 3 | F5: =IF($B5="","",IFERROR(INDEX('Liste des ingrédients'!$G$5:$G$98,MATCH($B5,'Liste des ingrédients'!$B$5:$B$98,0)),"?")) -> kg | G5: =IF(OR($B5="",$C5=""),0,IFERROR($C5*E5/IF(OR(F5="kg",F5="L"),1000,1),0)) -> 1.5 | H5: =IF(AND($A5<>"",$A5='Fiche plat'!$C$3),COUNTIF($A$5:$A5,'Fiche plat'!$C$3),"") -> 1 | I5: =IF($A5="","",IFERROR(INDEX(Plats!$D$5:$D$48,MATCH($A5,Plats!$I$5:$I$48,0)),"")) -> Oui
A6: Jour 1 Déjeuner – Couscous au poisson | B6: Poisson à chair ferme (mérou, loup, dorade) | C6: 1000 | D6: =IF($B6="","",IF(F6="kg","g",IF(F6="L","ml",F6))) -> g | E6: =IF($B6="","",IFERROR(INDEX('Liste des ingrédients'!$H$5:$H$98,MATCH($B6,'Liste des ingrédients'!$B$5:$B$98,0)),0)) -> 22 | F6: =IF($B6="","",IFERROR(INDEX('Liste des ingrédients'!$G$5:$G$98,MATCH($B6,'Liste des ingrédients'!$B$5:$B$98,0)),"?")) -> kg | G6: =IF(OR($B6="",$C6=""),0,IFERROR($C6*E6/IF(OR(F6="kg",F6="L"),1000,1),0)) -> 22 | H6: =IF(AND($A6<>"",$A6='Fiche plat'!$C$3),COUNTIF($A$5:$A6,'Fiche plat'!$C$3),"") -> 2 | I6: =IF($A6="","",IFERROR(INDEX(Plats!$D$5:$D$48,MATCH($A6,Plats!$I$5:$I$48,0)),"")) -> Oui
A7: Jour 1 Déjeuner – Couscous au poisson | B7: Carottes | C7: 300 | D7: =IF($B7="","",IF(F7="kg","g",IF(F7="L","ml",F7))) -> g | E7: =IF($B7="","",IFERROR(INDEX('Liste des ingrédients'!$H$5:$H$98,MATCH($B7,'Liste des ingrédients'!$B$5:$B$98,0)),0)) -> 2.5 | F7: =IF($B7="","",IFERROR(INDEX('Liste des ingrédients'!$G$5:$G$98,MATCH($B7,'Liste des ingrédients'!$B$5:$B$98,0)),"?")) -> kg | G7: =IF(OR($B7="",$C7=""),0,IFERROR($C7*E7/IF(OR(F7="kg",F7="L"),1000,1),0)) -> 0.75 | H7: =IF(AND($A7<>"",$A7='Fiche plat'!$C$3),COUNTIF($A$5:$A7,'Fiche plat'!$C$3),"") -> 3 | I7: =IF($A7="","",IFERROR(INDEX(Plats!$D$5:$D$48,MATCH($A7,Plats!$I$5:$I$48,0)),"")) -> Oui
A8: Jour 1 Déjeuner – Couscous au poisson | B8: Courgettes | C8: 300 | D8: =IF($B8="","",IF(F8="kg","g",IF(F8="L","ml",F8))) -> g | E8: =IF($B8="","",IFERROR(INDEX('Liste des ingrédients'!$H$5:$H$98,MATCH($B8,'Liste des ingrédients'!$B$5:$B$98,0)),0)) -> 2 | F8: =IF($B8="","",IFERROR(INDEX('Liste des ingrédients'!$G$5:$G$98,MATCH($B8,'Liste des ingrédients'!$B$5:$B$98,0)),"?")) -> kg | G8: =IF(OR($B8="",$C8=""),0,IFERROR($C8*E8/IF(OR(F8="kg",F8="L"),1000,1),0)) -> 0.6 | H8: =IF(AND($A8<>"",$A8='Fiche plat'!$C$3),COUNTIF($A$5:$A8,'Fiche plat'!$C$3),"") -> 4 | I8: =IF($A8="","",IFERROR(INDEX(Plats!$D$5:$D$48,MATCH($A8,Plats!$I$5:$I$48,0)),"")) -> Oui
A9: Jour 1 Déjeuner – Couscous au poisson | B9: Pommes de terre | C9: 400 | D9: =IF($B9="","",IF(F9="kg","g",IF(F9="L","ml",F9))) -> g | E9: =IF($B9="","",IFERROR(INDEX('Liste des ingrédients'!$H$5:$H$98,MATCH($B9,'Liste des ingrédients'!$B$5:$B$98,0)),0)) -> 2.5 | F9: =IF($B9="","",IFERROR(INDEX('Liste des ingrédients'!$G$5:$G$98,MATCH($B9,'Liste des ingrédients'!$B$5:$B$98,0)),"?")) -> kg | G9: =IF(OR($B9="",$C9=""),0,IFERROR($C9*E9/IF(OR(F9="kg",F9="L"),1000,1),0)) -> 1 | H9: =IF(AND($A9<>"",$A9='Fiche plat'!$C$3),COUNTIF($A$5:$A9,'Fiche plat'!$C$3),"") -> 5 | I9: =IF($A9="","",IFERROR(INDEX(Plats!$D$5:$D$48,MATCH($A9,Plats!$I$5:$I$48,0)),"")) -> Oui
A10: Jour 1 Déjeuner – Couscous au poisson | B10: Oignons | C10: 100 | D10: =IF($B10="","",IF(F10="kg","g",IF(F10="L","ml",F10))) -> g | E10: =IF($B10="","",IFERROR(INDEX('Liste des ingrédients'!$H$5:$H$98,MATCH($B10,'Liste des ingrédients'!$B$5:$B$98,0)),0)) -> 1.2 | F10: =IF($B10="","",IFERROR(INDEX('Liste des ingrédients'!$G$5:$G$98,MATCH($B10,'Liste des ingrédients'!$B$5:$B$98,0)),"?")) -> kg | G10: =IF(OR($B10="",$C10=""),0,IFERROR($C10*E10/IF(OR(F10="kg",F10="L"),1000,1),0)) -> 0.12 | H10: =IF(AND($A10<>"",$A10='Fiche plat'!$C$3),COUNTIF($A$5:$A10,'Fiche plat'!$C$3),"") -> 6 | I10: =IF($A10="","",IFERROR(INDEX(Plats!$D$5:$D$48,MATCH($A10,Plats!$I$5:$I$48,0)),"")) -> Oui
A11: Jour 1 Déjeuner – Couscous au poisson | B11: Piments verts | C11: 60 | D11: =IF($B11="","",IF(F11="kg","g",IF(F11="L","ml",F11))) -> g | E11: =IF($B11="","",IFERROR(INDEX('Liste des ingrédients'!$H$5:$H$98,MATCH($B11,'Liste des ingrédients'!$B$5:$B$98,0)),0)) -> 2.5 | F11: =IF($B11="","",IFERROR(INDEX('Liste des ingrédients'!$G$5:$G$98,MATCH($B11,'Liste des ingrédients'!$B$5:$B$98,0)),"?")) -> kg | G11: =IF(OR($B11="",$C11=""),0,IFERROR($C11*E11/IF(OR(F11="kg",F11="L"),1000,1),0)) -> 0.15 | H11: =IF(AND($A11<>"",$A11='Fiche plat'!$C$3),COUNTIF($A$5:$A11,'Fiche plat'!$C$3),"") -> 7 | I11: =IF($A11="","",IFERROR(INDEX(Plats!$D$5:$D$48,MATCH($A11,Plats!$I$5:$I$48,0)),"")) -> Oui
A12: Jour 1 Déjeuner – Couscous au poisson | B12: Concentré de tomate | C12: 40 | D12: =IF($B12="","",IF(F12="kg","g",IF(F12="L","ml",F12))) -> g | E12: =IF($B12="","",IFERROR(INDEX('Liste des ingrédients'!$H$5:$H$98,MATCH($B12,'Liste des ingrédients'!$B$5:$B$98,0)),0)) -> 9 | F12: =IF($B12="","",IFERROR(INDEX('Liste des ingrédients'!$G$5:$G$98,MATCH($B12,'Liste des ingrédients'!$B$5:$B$98,0)),"?")) -> kg | G12: =IF(OR($B12="",$C12=""),0,IFERROR($C12*E12/IF(OR(F12="kg",F12="L"),1000,1),0)) -> 0.36 | H12: =IF(AND($A12<>"",$A12='Fiche plat'!$C$3),COUNTIF($A$5:$A12,'Fiche plat'!$C$3),"") -> 8 | I12: =IF($A12="","",IFERROR(INDEX(Plats!$D$5:$D$48,MATCH($A12,Plats!$I$5:$I$48,0)),"")) -> Oui
A13: Jour 1 Déjeuner – Couscous au poisson | B13: Harissa | C13: 15 | D13: =IF($B13="","",IF(F13="kg","g",IF(F13="L","ml",F13))) -> g | E13: =IF($B13="","",IFERROR(INDEX('Liste des ingrédients'!$H$5:$H$98,MATCH($B13,'Liste des ingrédients'!$B$5:$B$98,0)),0)) -> 11 | F13: =IF($B13="","",IFERROR(INDEX('Liste des ingrédients'!$G$5:$G$98,MATCH($B13,'Liste des ingrédients'!$B$5:$B$98,0)),"?")) -> kg | G13: =IF(OR($B13="",$C13=""),0,IFERROR($C13*E13/IF(OR(F13="kg",F13="L"),1000,1),0)) -> 0.165 | H13: =IF(AND($A13<>"",$A13='Fiche plat'!$C$3),COUNTIF($A$5:$A13,'Fiche plat'!$C$3),"") -> 9 | I13: =IF($A13="","",IFERROR(INDEX(Plats!$D$5:$D$48,MATCH($A13,Plats!$I$5:$I$48,0)),"")) -> Oui
A14: Jour 1 Déjeuner – Couscous au poisson | B14: Ail | C14: 20 | D14: =IF($B14="","",IF(F14="kg","g",IF(F14="L","ml",F14))) -> g | E14: =IF($B14="","",IFERROR(INDEX('Liste des ingrédients'!$H$5:$H$98,MATCH($B14,'Liste des ingrédients'!$B$5:$B$98,0)),0)) -> 15 | F14: =IF($B14="","",IFERROR(INDEX('Liste des ingrédients'!$G$5:$G$98,MATCH($B14,'Liste des ingrédients'!$B$5:$B$98,0)),"?")) -> kg | G14: =IF(OR($B14="",$C14=""),0,IFERROR($C14*E14/IF(OR(F14="kg",F14="L"),1000,1),0)) -> 0.3 | H14: =IF(AND($A14<>"",$A14='Fiche plat'!$C$3),COUNTIF($A$5:$A14,'Fiche plat'!$C$3),"") -> 10 | I14: =IF($A14="","",IFERROR(INDEX(Plats!$D$5:$D$48,MATCH($A14,Plats!$I$5:$I$48,0)),"")) -> Oui
A15: Jour 1 Déjeuner – Couscous au poisson | B15: Curcuma | C15: 3 | D15: =IF($B15="","",IF(F15="kg","g",IF(F15="L","ml",F15))) -> g | E15: =IF($B15="","",IFERROR(INDEX('Liste des ingrédients'!$H$5:$H$98,MATCH($B15,'Liste des ingrédients'!$B$5:$B$98,0)),0)) -> 40 | F15: =IF($B15="","",IFERROR(INDEX('Liste des ingrédients'!$G$5:$G$98,MATCH($B15,'Liste des ingrédients'!$B$5:$B$98,0)),"?")) -> kg | G15: =IF(OR($B15="",$C15=""),0,IFERROR($C15*E15/IF(OR(F15="kg",F15="L"),1000,1),0)) -> 0.12 | H15: =IF(AND($A15<>"",$A15='Fiche plat'!$C$3),COUNTIF($A$5:$A15,'Fiche plat'!$C$3),"") -> 11 | I15: =IF($A15="","",IFERROR(INDEX(Plats!$D$5:$D$48,MATCH($A15,Plats!$I$5:$I$48,0)),"")) -> Oui
A16: Jour 1 Déjeuner – Couscous au poisson | B16: Carvi | C16: 2.5 | D16: =IF($B16="","",IF(F16="kg","g",IF(F16="L","ml",F16))) -> g | E16: =IF($B16="","",IFERROR(INDEX('Liste des ingrédients'!$H$5:$H$98,MATCH($B16,'Liste des ingrédients'!$B$5:$B$98,0)),0)) -> 40 | F16: =IF($B16="","",IFERROR(INDEX('Liste des ingrédients'!$G$5:$G$98,MATCH($B16,'Liste des ingrédients'!$B$5:$B$98,0)),"?")) -> kg | G16: =IF(OR($B16="",$C16=""),0,IFERROR($C16*E16/IF(OR(F16="kg",F16="L"),1000,1),0)) -> 0.1 | H16: =IF(AND($A16<>"",$A16='Fiche plat'!$C$3),COUNTIF($A$5:$A16,'Fiche plat'!$C$3),"") -> 12 | I16: =IF($A16="","",IFERROR(INDEX(Plats!$D$5:$D$48,MATCH($A16,Plats!$I$5:$I$48,0)),"")) -> Oui
... A396: Jour 1 à 14 Dessert – Fruits de saison (1 portion par personne et par jour) | B396: Dattes (Deglet Nour, branchées) | C396: 1000 | D396: =IF($B396="","",IF(F396="kg","g",IF(F396="L","ml",F396))) -> g | E396: =IF($B396="","",IFERROR(INDEX('Liste des ingrédients'!$H$5:$H$98,MATCH($B396,'Liste des ingrédients'!$B$5:$B$98,0)),0)) -> 5.17 | F396: =IF($B396="","",IFERROR(INDEX('Liste des ingrédients'!$G$5:$G$98,MATCH($B396,'Liste des ingrédients'!$B$5:$B$98,0)),"?")) -> kg | G396: =IF(OR($B396="",$C396=""),0,IFERROR($C396*E396/IF(OR(F396="kg",F396="L"),1000,1),0)) -> 5.17 | H396: =IF(AND($A396<>"",$A396='Fiche plat'!$C$3),COUNTIF($A$5:$A396,'Fiche plat'!$C$3),"") | I396: =IF($A396="","",IFERROR(INDEX(Plats!$D$5:$D$48,MATCH($A396,Plats!$I$5:$I$48,0)),"")) -> Oui
D397: =IF($B397="","",IF(F397="kg","g",IF(F397="L","ml",F397))) | E397: =IF($B397="","",IFERROR(INDEX('Liste des ingrédients'!$H$5:$H$98,MATCH($B397,'Liste des ingrédients'!$B$5:$B$98,0)),0)) | F397: =IF($B397="","",IFERROR(INDEX('Liste des ingrédients'!$G$5:$G$98,MATCH($B397,'Liste des ingrédients'!$B$5:$B$98,0)),"?")) | G397: =IF(OR($B397="",$C397=""),0,IFERROR($C397*E397/IF(OR(F397="kg",F397="L"),1000,1),0)) -> 0 | H397: =IF(AND($A397<>"",$A397='Fiche plat'!$C$3),COUNTIF($A$5:$A397,'Fiche plat'!$C$3),"") | I397: =IF($A397="","",IFERROR(INDEX(Plats!$D$5:$D$48,MATCH($A397,Plats!$I$5:$I$48,0)),""))
D398: =IF($B398="","",IF(F398="kg","g",IF(F398="L","ml",F398))) | E398: =IF($B398="","",IFERROR(INDEX('Liste des ingrédients'!$H$5:$H$98,MATCH($B398,'Liste des ingrédients'!$B$5:$B$98,0)),0)) | F398: =IF($B398="","",IFERROR(INDEX('Liste des ingrédients'!$G$5:$G$98,MATCH($B398,'Liste des ingrédients'!$B$5:$B$98,0)),"?")) | G398: =IF(OR($B398="",$C398=""),0,IFERROR($C398*E398/IF(OR(F398="kg",F398="L"),1000,1),0)) -> 0 | H398: =IF(AND($A398<>"",$A398='Fiche plat'!$C$3),COUNTIF($A$5:$A398,'Fiche plat'!$C$3),"") | I398: =IF($A398="","",IFERROR(INDEX(Plats!$D$5:$D$48,MATCH($A398,Plats!$I$5:$I$48,0)),""))
D399: =IF($B399="","",IF(F399="kg","g",IF(F399="L","ml",F399))) | E399: =IF($B399="","",IFERROR(INDEX('Liste des ingrédients'!$H$5:$H$98,MATCH($B399,'Liste des ingrédients'!$B$5:$B$98,0)),0)) | F399: =IF($B399="","",IFERROR(INDEX('Liste des ingrédients'!$G$5:$G$98,MATCH($B399,'Liste des ingrédients'!$B$5:$B$98,0)),"?")) | G399: =IF(OR($B399="",$C399=""),0,IFERROR($C399*E399/IF(OR(F399="kg",F399="L"),1000,1),0)) -> 0 | H399: =IF(AND($A399<>"",$A399='Fiche plat'!$C$3),COUNTIF($A$5:$A399,'Fiche plat'!$C$3),"") | I399: =IF($A399="","",IFERROR(INDEX(Plats!$D$5:$D$48,MATCH($A399,Plats!$I$5:$I$48,0)),""))
D400: =IF($B400="","",IF(F400="kg","g",IF(F400="L","ml",F400))) | E400: =IF($B400="","",IFERROR(INDEX('Liste des ingrédients'!$H$5:$H$98,MATCH($B400,'Liste des ingrédients'!$B$5:$B$98,0)),0)) | F400: =IF($B400="","",IFERROR(INDEX('Liste des ingrédients'!$G$5:$G$98,MATCH($B400,'Liste des ingrédients'!$B$5:$B$98,0)),"?")) | G400: =IF(OR($B400="",$C400=""),0,IFERROR($C400*E400/IF(OR(F400="kg",F400="L"),1000,1),0)) -> 0 | H400: =IF(AND($A400<>"",$A400='Fiche plat'!$C$3),COUNTIF($A$5:$A400,'Fiche plat'!$C$3),"") | I400: =IF($A400="","",IFERROR(INDEX(Plats!$D$5:$D$48,MATCH($A400,Plats!$I$5:$I$48,0)),""))
